No handlers could be found for logger "CREDENTIAL/65123"
Exception in thread Thread-1:
Traceback (most recent call last):
  File "/usr/lib/python2.6/threading.py", line 532, in __bootstrap_inner
    self.run()
  File "/usr/lib/python2.6/threading.py", line 484, in run
    self.__target(*self.__args, **self.__kwargs)
  File "/usr/local/lib/python2.6/dist-packages/rpyc/utils/server.py", line 178, in _authenticate_and_serve_client
    self._serve_client(sock2, credentials)
  File "/usr/local/lib/python2.6/dist-packages/rpyc/utils/server.py", line 201, in _serve_client
    conn._init_service()
  File "/usr/local/lib/python2.6/dist-packages/rpyc/core/protocol.py", line 150, in _init_service
    self._local_root.on_connect()
  File "/home/alice/tesla/CredentialMgr/credentialmanager.py", line 18, in on_connect
    debug( "Welkom")
TypeError: 'module' object is not callable

Exception TypeError: "'module' object is not callable" in <bound method Connection.__del__ of <rpyc.core.protocol.Connection 'conn1' object at 0xb6ebad4c>> ignored
Exception in thread Thread-2:
Traceback (most recent call last):
  File "/usr/lib/python2.6/threading.py", line 532, in __bootstrap_inner
    self.run()
  File "/usr/lib/python2.6/threading.py", line 484, in run
    self.__target(*self.__args, **self.__kwargs)
  File "/usr/local/lib/python2.6/dist-packages/rpyc/utils/server.py", line 178, in _authenticate_and_serve_client
    self._serve_client(sock2, credentials)
  File "/usr/local/lib/python2.6/dist-packages/rpyc/utils/server.py", line 201, in _serve_client
    conn._init_service()
  File "/usr/local/lib/python2.6/dist-packages/rpyc/core/protocol.py", line 150, in _init_service
    self._local_root.on_connect()
  File "/home/alice/tesla/CredentialMgr/credentialmanager.py", line 18, in on_connect
    debug( "Welkom")
TypeError: 'module' object is not callable

Exception TypeError: "'module' object is not callable" in <bound method Connection.__del__ of <rpyc.core.protocol.Connection 'conn2' object at 0xb6ebadac>> ignored
Exception in thread Thread-3:
Traceback (most recent call last):
  File "/usr/lib/python2.6/threading.py", line 532, in __bootstrap_inner
    self.run()
  File "/usr/lib/python2.6/threading.py", line 484, in run
    self.__target(*self.__args, **self.__kwargs)
  File "/usr/local/lib/python2.6/dist-packages/rpyc/utils/server.py", line 178, in _authenticate_and_serve_client
    self._serve_client(sock2, credentials)
  File "/usr/local/lib/python2.6/dist-packages/rpyc/utils/server.py", line 201, in _serve_client
    conn._init_service()
  File "/usr/local/lib/python2.6/dist-packages/rpyc/core/protocol.py", line 150, in _init_service
    self._local_root.on_connect()
  File "/home/alice/tesla/CredentialMgr/credentialmanager.py", line 18, in on_connect
    debug( "Welkom")
TypeError: 'module' object is not callable

Exception TypeError: "'module' object is not callable" in <bound method Connection.__del__ of <rpyc.core.protocol.Connection 'conn3' object at 0xb6ebadcc>> ignored
Exception in thread Thread-4:
Traceback (most recent call last):
  File "/usr/lib/python2.6/threading.py", line 532, in __bootstrap_inner
    self.run()
  File "/usr/lib/python2.6/threading.py", line 484, in run
    self.__target(*self.__args, **self.__kwargs)
  File "/usr/local/lib/python2.6/dist-packages/rpyc/utils/server.py", line 178, in _authenticate_and_serve_client
    self._serve_client(sock2, credentials)
  File "/usr/local/lib/python2.6/dist-packages/rpyc/utils/server.py", line 201, in _serve_client
    conn._init_service()
  File "/usr/local/lib/python2.6/dist-packages/rpyc/core/protocol.py", line 150, in _init_service
    self._local_root.on_connect()
  File "/home/alice/tesla/CredentialMgr/credentialmanager.py", line 18, in on_connect
    debug( "Welkom")
TypeError: 'module' object is not callable

Exception TypeError: "'module' object is not callable" in <bound method Connection.__del__ of <rpyc.core.protocol.Connection 'conn4' object at 0xb6ebad8c>> ignored
Exception in thread Thread-5:
Traceback (most recent call last):
  File "/usr/lib/python2.6/threading.py", line 532, in __bootstrap_inner
    self.run()
  File "/usr/lib/python2.6/threading.py", line 484, in run
    self.__target(*self.__args, **self.__kwargs)
  File "/usr/local/lib/python2.6/dist-packages/rpyc/utils/server.py", line 178, in _authenticate_and_serve_client
    self._serve_client(sock2, credentials)
  File "/usr/local/lib/python2.6/dist-packages/rpyc/utils/server.py", line 201, in _serve_client
    conn._init_service()
  File "/usr/local/lib/python2.6/dist-packages/rpyc/core/protocol.py", line 150, in _init_service
    self._local_root.on_connect()
  File "/home/alice/tesla/CredentialMgr/credentialmanager.py", line 18, in on_connect
    debug( "Welkom")
TypeError: 'module' object is not callable

Exception TypeError: "'module' object is not callable" in <bound method Connection.__del__ of <rpyc.core.protocol.Connection 'conn5' object at 0xb6ebad2c>> ignored
Exception in thread Thread-6:
Traceback (most recent call last):
  File "/usr/lib/python2.6/threading.py", line 532, in __bootstrap_inner
    self.run()
  File "/usr/lib/python2.6/threading.py", line 484, in run
    self.__target(*self.__args, **self.__kwargs)
  File "/usr/local/lib/python2.6/dist-packages/rpyc/utils/server.py", line 178, in _authenticate_and_serve_client
    self._serve_client(sock2, credentials)
  File "/usr/local/lib/python2.6/dist-packages/rpyc/utils/server.py", line 201, in _serve_client
    conn._init_service()
  File "/usr/local/lib/python2.6/dist-packages/rpyc/core/protocol.py", line 150, in _init_service
    self._local_root.on_connect()
  File "/home/alice/tesla/CredentialMgr/credentialmanager.py", line 18, in on_connect
    debug( "Welkom")
TypeError: 'module' object is not callable

Exception TypeError: "'module' object is not callable" in <bound method Connection.__del__ of <rpyc.core.protocol.Connection 'conn6' object at 0xb6ebad4c>> ignored
Exception in thread Thread-7:
Traceback (most recent call last):
  File "/usr/lib/python2.6/threading.py", line 532, in __bootstrap_inner
    self.run()
  File "/usr/lib/python2.6/threading.py", line 484, in run
    self.__target(*self.__args, **self.__kwargs)
  File "/usr/local/lib/python2.6/dist-packages/rpyc/utils/server.py", line 178, in _authenticate_and_serve_client
    self._serve_client(sock2, credentials)
  File "/usr/local/lib/python2.6/dist-packages/rpyc/utils/server.py", line 201, in _serve_client
    conn._init_service()
  File "/usr/local/lib/python2.6/dist-packages/rpyc/core/protocol.py", line 150, in _init_service
    self._local_root.on_connect()
  File "/home/alice/tesla/CredentialMgr/credentialmanager.py", line 18, in on_connect
    debug( "Welkom")
TypeError: 'module' object is not callable

Exception TypeError: "'module' object is not callable" in <bound method Connection.__del__ of <rpyc.core.protocol.Connection 'conn7' object at 0xb6ebadac>> ignored
Exception in thread Thread-8:
Traceback (most recent call last):
  File "/usr/lib/python2.6/threading.py", line 532, in __bootstrap_inner
    self.run()
  File "/usr/lib/python2.6/threading.py", line 484, in run
    self.__target(*self.__args, **self.__kwargs)
  File "/usr/local/lib/python2.6/dist-packages/rpyc/utils/server.py", line 178, in _authenticate_and_serve_client
    self._serve_client(sock2, credentials)
  File "/usr/local/lib/python2.6/dist-packages/rpyc/utils/server.py", line 201, in _serve_client
    conn._init_service()
  File "/usr/local/lib/python2.6/dist-packages/rpyc/core/protocol.py", line 150, in _init_service
    self._local_root.on_connect()
  File "/home/alice/tesla/CredentialMgr/credentialmanager.py", line 18, in on_connect
    debug( "Welkom")
TypeError: 'module' object is not callable

Exception TypeError: "'module' object is not callable" in <bound method Connection.__del__ of <rpyc.core.protocol.Connection 'conn8' object at 0xb6ebadcc>> ignored
Exception in thread Thread-9:
Traceback (most recent call last):
  File "/usr/lib/python2.6/threading.py", line 532, in __bootstrap_inner
    self.run()
  File "/usr/lib/python2.6/threading.py", line 484, in run
    self.__target(*self.__args, **self.__kwargs)
  File "/usr/local/lib/python2.6/dist-packages/rpyc/utils/server.py", line 178, in _authenticate_and_serve_client
    self._serve_client(sock2, credentials)
  File "/usr/local/lib/python2.6/dist-packages/rpyc/utils/server.py", line 201, in _serve_client
    conn._init_service()
  File "/usr/local/lib/python2.6/dist-packages/rpyc/core/protocol.py", line 150, in _init_service
    self._local_root.on_connect()
  File "/home/alice/tesla/CredentialMgr/credentialmanager.py", line 18, in on_connect
    debug( "Welkom")
TypeError: 'module' object is not callable

Exception TypeError: "'module' object is not callable" in <bound method Connection.__del__ of <rpyc.core.protocol.Connection 'conn9' object at 0xb6ebad8c>> ignored
Exception in thread Thread-10:
Traceback (most recent call last):
  File "/usr/lib/python2.6/threading.py", line 532, in __bootstrap_inner
    self.run()
  File "/usr/lib/python2.6/threading.py", line 484, in run
    self.__target(*self.__args, **self.__kwargs)
  File "/usr/local/lib/python2.6/dist-packages/rpyc/utils/server.py", line 178, in _authenticate_and_serve_client
    self._serve_client(sock2, credentials)
  File "/usr/local/lib/python2.6/dist-packages/rpyc/utils/server.py", line 201, in _serve_client
    conn._init_service()
  File "/usr/local/lib/python2.6/dist-packages/rpyc/core/protocol.py", line 150, in _init_service
    self._local_root.on_connect()
  File "/home/alice/tesla/CredentialMgr/credentialmanager.py", line 18, in on_connect
    debug( "Welkom")
TypeError: 'module' object is not callable

Exception TypeError: "'module' object is not callable" in <bound method Connection.__del__ of <rpyc.core.protocol.Connection 'conn10' object at 0xb6ebad8c>> ignored
Exception in thread Thread-11:
Traceback (most recent call last):
  File "/usr/lib/python2.6/threading.py", line 532, in __bootstrap_inner
    self.run()
  File "/usr/lib/python2.6/threading.py", line 484, in run
    self.__target(*self.__args, **self.__kwargs)
  File "/usr/local/lib/python2.6/dist-packages/rpyc/utils/server.py", line 178, in _authenticate_and_serve_client
    self._serve_client(sock2, credentials)
  File "/usr/local/lib/python2.6/dist-packages/rpyc/utils/server.py", line 201, in _serve_client
    conn._init_service()
  File "/usr/local/lib/python2.6/dist-packages/rpyc/core/protocol.py", line 150, in _init_service
    self._local_root.on_connect()
  File "/home/alice/tesla/CredentialMgr/credentialmanager.py", line 18, in on_connect
    debug( "Welkom")
TypeError: 'module' object is not callable

Exception TypeError: "'module' object is not callable" in <bound method Connection.__del__ of <rpyc.core.protocol.Connection 'conn11' object at 0xb6ebadcc>> ignored
Exception in thread Thread-12:
Traceback (most recent call last):
  File "/usr/lib/python2.6/threading.py", line 532, in __bootstrap_inner
    self.run()
  File "/usr/lib/python2.6/threading.py", line 484, in run
    self.__target(*self.__args, **self.__kwargs)
  File "/usr/local/lib/python2.6/dist-packages/rpyc/utils/server.py", line 178, in _authenticate_and_serve_client
    self._serve_client(sock2, credentials)
  File "/usr/local/lib/python2.6/dist-packages/rpyc/utils/server.py", line 201, in _serve_client
    conn._init_service()
  File "/usr/local/lib/python2.6/dist-packages/rpyc/core/protocol.py", line 150, in _init_service
    self._local_root.on_connect()
  File "/home/alice/tesla/CredentialMgr/credentialmanager.py", line 18, in on_connect
    debug( "Welkom")
TypeError: 'module' object is not callable

Exception TypeError: "'module' object is not callable" in <bound method Connection.__del__ of <rpyc.core.protocol.Connection 'conn12' object at 0xb6ebad4c>> ignored
Exception in thread Thread-13:
Traceback (most recent call last):
  File "/usr/lib/python2.6/threading.py", line 532, in __bootstrap_inner
    self.run()
  File "/usr/lib/python2.6/threading.py", line 484, in run
    self.__target(*self.__args, **self.__kwargs)
  File "/usr/local/lib/python2.6/dist-packages/rpyc/utils/server.py", line 178, in _authenticate_and_serve_client
    self._serve_client(sock2, credentials)
  File "/usr/local/lib/python2.6/dist-packages/rpyc/utils/server.py", line 201, in _serve_client
    conn._init_service()
  File "/usr/local/lib/python2.6/dist-packages/rpyc/core/protocol.py", line 150, in _init_service
    self._local_root.on_connect()
  File "/home/alice/tesla/CredentialMgr/credentialmanager.py", line 18, in on_connect
    debug( "Welkom")
TypeError: 'module' object is not callable

Exception TypeError: "'module' object is not callable" in <bound method Connection.__del__ of <rpyc.core.protocol.Connection 'conn13' object at 0xb6ebad2c>> ignored
Exception in thread Thread-14:
Traceback (most recent call last):
  File "/usr/lib/python2.6/threading.py", line 532, in __bootstrap_inner
    self.run()
  File "/usr/lib/python2.6/threading.py", line 484, in run
    self.__target(*self.__args, **self.__kwargs)
  File "/usr/local/lib/python2.6/dist-packages/rpyc/utils/server.py", line 178, in _authenticate_and_serve_client
    self._serve_client(sock2, credentials)
  File "/usr/local/lib/python2.6/dist-packages/rpyc/utils/server.py", line 201, in _serve_client
    conn._init_service()
  File "/usr/local/lib/python2.6/dist-packages/rpyc/core/protocol.py", line 150, in _init_service
    self._local_root.on_connect()
  File "/home/alice/tesla/CredentialMgr/credentialmanager.py", line 18, in on_connect
    debug( "Welkom")
TypeError: 'module' object is not callable

Exception TypeError: "'module' object is not callable" in <bound method Connection.__del__ of <rpyc.core.protocol.Connection 'conn14' object at 0xb6ebac6c>> ignored
Exception in thread Thread-15:
Traceback (most recent call last):
  File "/usr/lib/python2.6/threading.py", line 532, in __bootstrap_inner
    self.run()
  File "/usr/lib/python2.6/threading.py", line 484, in run
    self.__target(*self.__args, **self.__kwargs)
  File "/usr/local/lib/python2.6/dist-packages/rpyc/utils/server.py", line 178, in _authenticate_and_serve_client
    self._serve_client(sock2, credentials)
  File "/usr/local/lib/python2.6/dist-packages/rpyc/utils/server.py", line 201, in _serve_client
    conn._init_service()
  File "/usr/local/lib/python2.6/dist-packages/rpyc/core/protocol.py", line 150, in _init_service
    self._local_root.on_connect()
  File "/home/alice/tesla/CredentialMgr/credentialmanager.py", line 18, in on_connect
    debug( "Welkom")
TypeError: 'module' object is not callable

Exception TypeError: "'module' object is not callable" in <bound method Connection.__del__ of <rpyc.core.protocol.Connection 'conn15' object at 0xb6ebad8c>> ignored
Exception in thread Thread-16:
Traceback (most recent call last):
  File "/usr/lib/python2.6/threading.py", line 532, in __bootstrap_inner
    self.run()
  File "/usr/lib/python2.6/threading.py", line 484, in run
    self.__target(*self.__args, **self.__kwargs)
  File "/usr/local/lib/python2.6/dist-packages/rpyc/utils/server.py", line 178, in _authenticate_and_serve_client
    self._serve_client(sock2, credentials)
  File "/usr/local/lib/python2.6/dist-packages/rpyc/utils/server.py", line 201, in _serve_client
    conn._init_service()
  File "/usr/local/lib/python2.6/dist-packages/rpyc/core/protocol.py", line 150, in _init_service
    self._local_root.on_connect()
  File "/home/alice/tesla/CredentialMgr/credentialmanager.py", line 18, in on_connect
    debug( "Welkom")
TypeError: 'module' object is not callable

Exception TypeError: "'module' object is not callable" in <bound method Connection.__del__ of <rpyc.core.protocol.Connection 'conn16' object at 0xb6ebadcc>> ignored
Exception in thread Thread-17:
Traceback (most recent call last):
  File "/usr/lib/python2.6/threading.py", line 532, in __bootstrap_inner
    self.run()
  File "/usr/lib/python2.6/threading.py", line 484, in run
    self.__target(*self.__args, **self.__kwargs)
  File "/usr/local/lib/python2.6/dist-packages/rpyc/utils/server.py", line 178, in _authenticate_and_serve_client
    self._serve_client(sock2, credentials)
  File "/usr/local/lib/python2.6/dist-packages/rpyc/utils/server.py", line 201, in _serve_client
    conn._init_service()
  File "/usr/local/lib/python2.6/dist-packages/rpyc/core/protocol.py", line 150, in _init_service
    self._local_root.on_connect()
  File "/home/alice/tesla/CredentialMgr/credentialmanager.py", line 18, in on_connect
    debug( "Welkom")
TypeError: 'module' object is not callable

Exception TypeError: "'module' object is not callable" in <bound method Connection.__del__ of <rpyc.core.protocol.Connection 'conn17' object at 0xb6ebad4c>> ignored
