No handlers could be found for logger "CREDENTIAL/65123"
Exception in thread Thread-1:
Traceback (most recent call last):
  File "/usr/lib/python2.6/threading.py", line 532, in __bootstrap_inner
    self.run()
  File "/usr/lib/python2.6/threading.py", line 484, in run
    self.__target(*self.__args, **self.__kwargs)
  File "/usr/local/lib/python2.6/dist-packages/rpyc/utils/server.py", line 178, in _authenticate_and_serve_client
    self._serve_client(sock2, credentials)
  File "/usr/local/lib/python2.6/dist-packages/rpyc/utils/server.py", line 201, in _serve_client
    conn._init_service()
  File "/usr/local/lib/python2.6/dist-packages/rpyc/core/protocol.py", line 150, in _init_service
    self._local_root.on_connect()
  File "/home/alice/tesla/CredentialMgr/credentialmanager.py", line 18, in on_connect
    debug( "Welkom")
TypeError: 'module' object is not callable

Exception TypeError: "'module' object is not callable" in <bound method Connection.__del__ of <rpyc.core.protocol.Connection 'conn1' object at 0xb6ebad4c>> ignored
Exception in thread Thread-2:
Traceback (most recent call last):
  File "/usr/lib/python2.6/threading.py", line 532, in __bootstrap_inner
    self.run()
  File "/usr/lib/python2.6/threading.py", line 484, in run
    self.__target(*self.__args, **self.__kwargs)
  File "/usr/local/lib/python2.6/dist-packages/rpyc/utils/server.py", line 178, in _authenticate_and_serve_client
    self._serve_client(sock2, credentials)
  File "/usr/local/lib/python2.6/dist-packages/rpyc/utils/server.py", line 201, in _serve_client
    conn._init_service()
  File "/usr/local/lib/python2.6/dist-packages/rpyc/core/protocol.py", line 150, in _init_service
    self._local_root.on_connect()
  File "/home/alice/tesla/CredentialMgr/credentialmanager.py", line 18, in on_connect
    debug( "Welkom")
TypeError: 'module' object is not callable

Exception TypeError: "'module' object is not callable" in <bound method Connection.__del__ of <rpyc.core.protocol.Connection 'conn2' object at 0xb6ebadac>> ignored
Exception in thread Thread-3:
Traceback (most recent call last):
  File "/usr/lib/python2.6/threading.py", line 532, in __bootstrap_inner
    self.run()
  File "/usr/lib/python2.6/threading.py", line 484, in run
    self.__target(*self.__args, **self.__kwargs)
  File "/usr/local/lib/python2.6/dist-packages/rpyc/utils/server.py", line 178, in _authenticate_and_serve_client
    self._serve_client(sock2, credentials)
  File "/usr/local/lib/python2.6/dist-packages/rpyc/utils/server.py", line 201, in _serve_client
    conn._init_service()
  File "/usr/local/lib/python2.6/dist-packages/rpyc/core/protocol.py", line 150, in _init_service
    self._local_root.on_connect()
  File "/home/alice/tesla/CredentialMgr/credentialmanager.py", line 18, in on_connect
    debug( "Welkom")
TypeError: 'module' object is not callable

Exception TypeError: "'module' object is not callable" in <bound method Connection.__del__ of <rpyc.core.protocol.Connection 'conn3' object at 0xb6ebadcc>> ignored
Exception in thread Thread-4:
Traceback (most recent call last):
  File "/usr/lib/python2.6/threading.py", line 532, in __bootstrap_inner
    self.run()
  File "/usr/lib/python2.6/threading.py", line 484, in run
    self.__target(*self.__args, **self.__kwargs)
  File "/usr/local/lib/python2.6/dist-packages/rpyc/utils/server.py", line 178, in _authenticate_and_serve_client
    self._serve_client(sock2, credentials)
  File "/usr/local/lib/python2.6/dist-packages/rpyc/utils/server.py", line 201, in _serve_client
    conn._init_service()
  File "/usr/local/lib/python2.6/dist-packages/rpyc/core/protocol.py", line 150, in _init_service
    self._local_root.on_connect()
  File "/home/alice/tesla/CredentialMgr/credentialmanager.py", line 18, in on_connect
    debug( "Welkom")
TypeError: 'module' object is not callable

Exception TypeError: "'module' object is not callable" in <bound method Connection.__del__ of <rpyc.core.protocol.Connection 'conn4' object at 0xb6ebad8c>> ignored
Exception in thread Thread-5:
Traceback (most recent call last):
  File "/usr/lib/python2.6/threading.py", line 532, in __bootstrap_inner
    self.run()
  File "/usr/lib/python2.6/threading.py", line 484, in run
    self.__target(*self.__args, **self.__kwargs)
  File "/usr/local/lib/python2.6/dist-packages/rpyc/utils/server.py", line 178, in _authenticate_and_serve_client
    self._serve_client(sock2, credentials)
  File "/usr/local/lib/python2.6/dist-packages/rpyc/utils/server.py", line 201, in _serve_client
    conn._init_service()
  File "/usr/local/lib/python2.6/dist-packages/rpyc/core/protocol.py", line 150, in _init_service
    self._local_root.on_connect()
  File "/home/alice/tesla/CredentialMgr/credentialmanager.py", line 18, in on_connect
    debug( "Welkom")
TypeError: 'module' object is not callable

Exception TypeError: "'module' object is not callable" in <bound method Connection.__del__ of <rpyc.core.protocol.Connection 'conn5' object at 0xb6ebad2c>> ignored
Exception in thread Thread-6:
Traceback (most recent call last):
  File "/usr/lib/python2.6/threading.py", line 532, in __bootstrap_inner
    self.run()
  File "/usr/lib/python2.6/threading.py", line 484, in run
    self.__target(*self.__args, **self.__kwargs)
  File "/usr/local/lib/python2.6/dist-packages/rpyc/utils/server.py", line 178, in _authenticate_and_serve_client
    self._serve_client(sock2, credentials)
  File "/usr/local/lib/python2.6/dist-packages/rpyc/utils/server.py", line 201, in _serve_client
    conn._init_service()
  File "/usr/local/lib/python2.6/dist-packages/rpyc/core/protocol.py", line 150, in _init_service
    self._local_root.on_connect()
  File "/home/alice/tesla/CredentialMgr/credentialmanager.py", line 18, in on_connect
    debug( "Welkom")
TypeError: 'module' object is not callable

Exception TypeError: "'module' object is not callable" in <bound method Connection.__del__ of <rpyc.core.protocol.Connection 'conn6' object at 0xb6ebad4c>> ignored
Exception in thread Thread-7:
Traceback (most recent call last):
  File "/usr/lib/python2.6/threading.py", line 532, in __bootstrap_inner
    self.run()
  File "/usr/lib/python2.6/threading.py", line 484, in run
    self.__target(*self.__args, **self.__kwargs)
  File "/usr/local/lib/python2.6/dist-packages/rpyc/utils/server.py", line 178, in _authenticate_and_serve_client
    self._serve_client(sock2, credentials)
  File "/usr/local/lib/python2.6/dist-packages/rpyc/utils/server.py", line 201, in _serve_client
    conn._init_service()
  File "/usr/local/lib/python2.6/dist-packages/rpyc/core/protocol.py", line 150, in _init_service
    self._local_root.on_connect()
  File "/home/alice/tesla/CredentialMgr/credentialmanager.py", line 18, in on_connect
    debug( "Welkom")
TypeError: 'module' object is not callable

Exception TypeError: "'module' object is not callable" in <bound method Connection.__del__ of <rpyc.core.protocol.Connection 'conn7' object at 0xb6ebadac>> ignored
Exception in thread Thread-8:
Traceback (most recent call last):
  File "/usr/lib/python2.6/threading.py", line 532, in __bootstrap_inner
    self.run()
  File "/usr/lib/python2.6/threading.py", line 484, in run
    self.__target(*self.__args, **self.__kwargs)
  File "/usr/local/lib/python2.6/dist-packages/rpyc/utils/server.py", line 178, in _authenticate_and_serve_client
    self._serve_client(sock2, credentials)
  File "/usr/local/lib/python2.6/dist-packages/rpyc/utils/server.py", line 201, in _serve_client
    conn._init_service()
  File "/usr/local/lib/python2.6/dist-packages/rpyc/core/protocol.py", line 150, in _init_service
    self._local_root.on_connect()
  File "/home/alice/tesla/CredentialMgr/credentialmanager.py", line 18, in on_connect
    debug( "Welkom")
TypeError: 'module' object is not callable

Exception TypeError: "'module' object is not callable" in <bound method Connection.__del__ of <rpyc.core.protocol.Connection 'conn8' object at 0xb6ebadcc>> ignored
Exception in thread Thread-9:
Traceback (most recent call last):
  File "/usr/lib/python2.6/threading.py", line 532, in __bootstrap_inner
    self.run()
  File "/usr/lib/python2.6/threading.py", line 484, in run
    self.__target(*self.__args, **self.__kwargs)
  File "/usr/local/lib/python2.6/dist-packages/rpyc/utils/server.py", line 178, in _authenticate_and_serve_client
    self._serve_client(sock2, credentials)
  File "/usr/local/lib/python2.6/dist-packages/rpyc/utils/server.py", line 201, in _serve_client
    conn._init_service()
  File "/usr/local/lib/python2.6/dist-packages/rpyc/core/protocol.py", line 150, in _init_service
    self._local_root.on_connect()
  File "/home/alice/tesla/CredentialMgr/credentialmanager.py", line 18, in on_connect
    debug( "Welkom")
TypeError: 'module' object is not callable

Exception TypeError: "'module' object is not callable" in <bound method Connection.__del__ of <rpyc.core.protocol.Connection 'conn9' object at 0xb6ebad8c>> ignored
Exception in thread Thread-10:
Traceback (most recent call last):
  File "/usr/lib/python2.6/threading.py", line 532, in __bootstrap_inner
    self.run()
  File "/usr/lib/python2.6/threading.py", line 484, in run
    self.__target(*self.__args, **self.__kwargs)
  File "/usr/local/lib/python2.6/dist-packages/rpyc/utils/server.py", line 178, in _authenticate_and_serve_client
    self._serve_client(sock2, credentials)
  File "/usr/local/lib/python2.6/dist-packages/rpyc/utils/server.py", line 201, in _serve_client
    conn._init_service()
  File "/usr/local/lib/python2.6/dist-packages/rpyc/core/protocol.py", line 150, in _init_service
    self._local_root.on_connect()
  File "/home/alice/tesla/CredentialMgr/credentialmanager.py", line 18, in on_connect
    debug( "Welkom")
TypeError: 'module' object is not callable

Exception TypeError: "'module' object is not callable" in <bound method Connection.__del__ of <rpyc.core.protocol.Connection 'conn10' object at 0xb6ebad8c>> ignored
Exception in thread Thread-11:
Traceback (most recent call last):
  File "/usr/lib/python2.6/threading.py", line 532, in __bootstrap_inner
    self.run()
  File "/usr/lib/python2.6/threading.py", line 484, in run
    self.__target(*self.__args, **self.__kwargs)
  File "/usr/local/lib/python2.6/dist-packages/rpyc/utils/server.py", line 178, in _authenticate_and_serve_client
    self._serve_client(sock2, credentials)
  File "/usr/local/lib/python2.6/dist-packages/rpyc/utils/server.py", line 201, in _serve_client
    conn._init_service()
  File "/usr/local/lib/python2.6/dist-packages/rpyc/core/protocol.py", line 150, in _init_service
    self._local_root.on_connect()
  File "/home/alice/tesla/CredentialMgr/credentialmanager.py", line 18, in on_connect
    debug( "Welkom")
TypeError: 'module' object is not callable

Exception TypeError: "'module' object is not callable" in <bound method Connection.__del__ of <rpyc.core.protocol.Connection 'conn11' object at 0xb6ebadcc>> ignored
Exception in thread Thread-12:
Traceback (most recent call last):
  File "/usr/lib/python2.6/threading.py", line 532, in __bootstrap_inner
    self.run()
  File "/usr/lib/python2.6/threading.py", line 484, in run
    self.__target(*self.__args, **self.__kwargs)
  File "/usr/local/lib/python2.6/dist-packages/rpyc/utils/server.py", line 178, in _authenticate_and_serve_client
    self._serve_client(sock2, credentials)
  File "/usr/local/lib/python2.6/dist-packages/rpyc/utils/server.py", line 201, in _serve_client
    conn._init_service()
  File "/usr/local/lib/python2.6/dist-packages/rpyc/core/protocol.py", line 150, in _init_service
    self._local_root.on_connect()
  File "/home/alice/tesla/CredentialMgr/credentialmanager.py", line 18, in on_connect
    debug( "Welkom")
TypeError: 'module' object is not callable

Exception TypeError: "'module' object is not callable" in <bound method Connection.__del__ of <rpyc.core.protocol.Connection 'conn12' object at 0xb6ebad4c>> ignored
Exception in thread Thread-13:
Traceback (most recent call last):
  File "/usr/lib/python2.6/threading.py", line 532, in __bootstrap_inner
    self.run()
  File "/usr/lib/python2.6/threading.py", line 484, in run
    self.__target(*self.__args, **self.__kwargs)
  File "/usr/local/lib/python2.6/dist-packages/rpyc/utils/server.py", line 178, in _authenticate_and_serve_client
    self._serve_client(sock2, credentials)
  File "/usr/local/lib/python2.6/dist-packages/rpyc/utils/server.py", line 201, in _serve_client
    conn._init_service()
  File "/usr/local/lib/python2.6/dist-packages/rpyc/core/protocol.py", line 150, in _init_service
    self._local_root.on_connect()
  File "/home/alice/tesla/CredentialMgr/credentialmanager.py", line 18, in on_connect
    debug( "Welkom")
TypeError: 'module' object is not callable

Exception TypeError: "'module' object is not callable" in <bound method Connection.__del__ of <rpyc.core.protocol.Connection 'conn13' object at 0xb6ebad2c>> ignored
Exception in thread Thread-14:
Traceback (most recent call last):
  File "/usr/lib/python2.6/threading.py", line 532, in __bootstrap_inner
    self.run()
  File "/usr/lib/python2.6/threading.py", line 484, in run
    self.__target(*self.__args, **self.__kwargs)
  File "/usr/local/lib/python2.6/dist-packages/rpyc/utils/server.py", line 178, in _authenticate_and_serve_client
    self._serve_client(sock2, credentials)
  File "/usr/local/lib/python2.6/dist-packages/rpyc/utils/server.py", line 201, in _serve_client
    conn._init_service()
  File "/usr/local/lib/python2.6/dist-packages/rpyc/core/protocol.py", line 150, in _init_service
    self._local_root.on_connect()
  File "/home/alice/tesla/CredentialMgr/credentialmanager.py", line 18, in on_connect
    debug( "Welkom")
TypeError: 'module' object is not callable

Exception TypeError: "'module' object is not callable" in <bound method Connection.__del__ of <rpyc.core.protocol.Connection 'conn14' object at 0xb6ebac6c>> ignored
Exception in thread Thread-15:
Traceback (most recent call last):
  File "/usr/lib/python2.6/threading.py", line 532, in __bootstrap_inner
    self.run()
  File "/usr/lib/python2.6/threading.py", line 484, in run
    self.__target(*self.__args, **self.__kwargs)
  File "/usr/local/lib/python2.6/dist-packages/rpyc/utils/server.py", line 178, in _authenticate_and_serve_client
    self._serve_client(sock2, credentials)
  File "/usr/local/lib/python2.6/dist-packages/rpyc/utils/server.py", line 201, in _serve_client
    conn._init_service()
  File "/usr/local/lib/python2.6/dist-packages/rpyc/core/protocol.py", line 150, in _init_service
    self._local_root.on_connect()
  File "/home/alice/tesla/CredentialMgr/credentialmanager.py", line 18, in on_connect
    debug( "Welkom")
TypeError: 'module' object is not callable

Exception TypeError: "'module' object is not callable" in <bound method Connection.__del__ of <rpyc.core.protocol.Connection 'conn15' object at 0xb6ebad8c>> ignored
Exception in thread Thread-16:
Traceback (most recent call last):
  File "/usr/lib/python2.6/threading.py", line 532, in __bootstrap_inner
    self.run()
  File "/usr/lib/python2.6/threading.py", line 484, in run
    self.__target(*self.__args, **self.__kwargs)
  File "/usr/local/lib/python2.6/dist-packages/rpyc/utils/server.py", line 178, in _authenticate_and_serve_client
    self._serve_client(sock2, credentials)
  File "/usr/local/lib/python2.6/dist-packages/rpyc/utils/server.py", line 201, in _serve_client
    conn._init_service()
  File "/usr/local/lib/python2.6/dist-packages/rpyc/core/protocol.py", line 150, in _init_service
    self._local_root.on_connect()
  File "/home/alice/tesla/CredentialMgr/credentialmanager.py", line 18, in on_connect
    debug( "Welkom")
TypeError: 'module' object is not callable

Exception TypeError: "'module' object is not callable" in <bound method Connection.__del__ of <rpyc.core.protocol.Connection 'conn16' object at 0xb6ebadcc>> ignored
Exception in thread Thread-17:
Traceback (most recent call last):
  File "/usr/lib/python2.6/threading.py", line 532, in __bootstrap_inner
    self.run()
  File "/usr/lib/python2.6/threading.py", line 484, in run
    self.__target(*self.__args, **self.__kwargs)
  File "/usr/local/lib/python2.6/dist-packages/rpyc/utils/server.py", line 178, in _authenticate_and_serve_client
    self._serve_client(sock2, credentials)
  File "/usr/local/lib/python2.6/dist-packages/rpyc/utils/server.py", line 201, in _serve_client
    conn._init_service()
  File "/usr/local/lib/python2.6/dist-packages/rpyc/core/protocol.py", line 150, in _init_service
    self._local_root.on_connect()
  File "/home/alice/tesla/CredentialMgr/credentialmanager.py", line 18, in on_connect
    debug( "Welkom")
TypeError: 'module' object is not callable

Exception TypeError: "'module' object is not callable" in <bound method Connection.__del__ of <rpyc.core.protocol.Connection 'conn17' object at 0xb6ebad4c>> ignored
Exception in thread Thread-18:
Traceback (most recent call last):
  File "/usr/lib/python2.6/threading.py", line 532, in __bootstrap_inner
    self.run()
  File "/usr/lib/python2.6/threading.py", line 484, in run
    self.__target(*self.__args, **self.__kwargs)
  File "/usr/local/lib/python2.6/dist-packages/rpyc/utils/server.py", line 178, in _authenticate_and_serve_client
    self._serve_client(sock2, credentials)
  File "/usr/local/lib/python2.6/dist-packages/rpyc/utils/server.py", line 201, in _serve_client
    conn._init_service()
  File "/usr/local/lib/python2.6/dist-packages/rpyc/core/protocol.py", line 150, in _init_service
    self._local_root.on_connect()
  File "/home/alice/tesla/CredentialMgr/credentialmanager.py", line 18, in on_connect
    debug( "Welkom")
TypeError: 'module' object is not callable

Exception TypeError: "'module' object is not callable" in <bound method Connection.__del__ of <rpyc.core.protocol.Connection 'conn18' object at 0xb6ebad2c>> ignored
Exception in thread Thread-19:
Traceback (most recent call last):
  File "/usr/lib/python2.6/threading.py", line 532, in __bootstrap_inner
    self.run()
  File "/usr/lib/python2.6/threading.py", line 484, in run
    self.__target(*self.__args, **self.__kwargs)
  File "/usr/local/lib/python2.6/dist-packages/rpyc/utils/server.py", line 178, in _authenticate_and_serve_client
    self._serve_client(sock2, credentials)
  File "/usr/local/lib/python2.6/dist-packages/rpyc/utils/server.py", line 201, in _serve_client
    conn._init_service()
  File "/usr/local/lib/python2.6/dist-packages/rpyc/core/protocol.py", line 150, in _init_service
    self._local_root.on_connect()
  File "/home/alice/tesla/CredentialMgr/credentialmanager.py", line 18, in on_connect
    debug( "Welkom")
TypeError: 'module' object is not callable

Exception TypeError: "'module' object is not callable" in <bound method Connection.__del__ of <rpyc.core.protocol.Connection 'conn19' object at 0xb6ebac6c>> ignored
Exception in thread Thread-20:
Traceback (most recent call last):
  File "/usr/lib/python2.6/threading.py", line 532, in __bootstrap_inner
    self.run()
  File "/usr/lib/python2.6/threading.py", line 484, in run
    self.__target(*self.__args, **self.__kwargs)
  File "/usr/local/lib/python2.6/dist-packages/rpyc/utils/server.py", line 178, in _authenticate_and_serve_client
    self._serve_client(sock2, credentials)
  File "/usr/local/lib/python2.6/dist-packages/rpyc/utils/server.py", line 201, in _serve_client
    conn._init_service()
  File "/usr/local/lib/python2.6/dist-packages/rpyc/core/protocol.py", line 150, in _init_service
    self._local_root.on_connect()
  File "/home/alice/tesla/CredentialMgr/credentialmanager.py", line 18, in on_connect
    debug( "Welkom")
TypeError: 'module' object is not callable

Exception TypeError: "'module' object is not callable" in <bound method Connection.__del__ of <rpyc.core.protocol.Connection 'conn20' object at 0xb6ebad8c>> ignored
Exception in thread Thread-21:
Traceback (most recent call last):
  File "/usr/lib/python2.6/threading.py", line 532, in __bootstrap_inner
    self.run()
  File "/usr/lib/python2.6/threading.py", line 484, in run
    self.__target(*self.__args, **self.__kwargs)
  File "/usr/local/lib/python2.6/dist-packages/rpyc/utils/server.py", line 178, in _authenticate_and_serve_client
    self._serve_client(sock2, credentials)
  File "/usr/local/lib/python2.6/dist-packages/rpyc/utils/server.py", line 201, in _serve_client
    conn._init_service()
  File "/usr/local/lib/python2.6/dist-packages/rpyc/core/protocol.py", line 150, in _init_service
    self._local_root.on_connect()
  File "/home/alice/tesla/CredentialMgr/credentialmanager.py", line 18, in on_connect
    debug( "Welkom")
TypeError: 'module' object is not callable

Exception TypeError: "'module' object is not callable" in <bound method Connection.__del__ of <rpyc.core.protocol.Connection 'conn21' object at 0xb6ebadcc>> ignored
Exception in thread Thread-22:
Traceback (most recent call last):
  File "/usr/lib/python2.6/threading.py", line 532, in __bootstrap_inner
    self.run()
  File "/usr/lib/python2.6/threading.py", line 484, in run
    self.__target(*self.__args, **self.__kwargs)
  File "/usr/local/lib/python2.6/dist-packages/rpyc/utils/server.py", line 178, in _authenticate_and_serve_client
    self._serve_client(sock2, credentials)
  File "/usr/local/lib/python2.6/dist-packages/rpyc/utils/server.py", line 201, in _serve_client
    conn._init_service()
  File "/usr/local/lib/python2.6/dist-packages/rpyc/core/protocol.py", line 150, in _init_service
    self._local_root.on_connect()
  File "/home/alice/tesla/CredentialMgr/credentialmanager.py", line 18, in on_connect
    debug( "Welkom")
TypeError: 'module' object is not callable

Exception TypeError: "'module' object is not callable" in <bound method Connection.__del__ of <rpyc.core.protocol.Connection 'conn22' object at 0xb6ebad4c>> ignored
Exception in thread Thread-23:
Traceback (most recent call last):
  File "/usr/lib/python2.6/threading.py", line 532, in __bootstrap_inner
    self.run()
  File "/usr/lib/python2.6/threading.py", line 484, in run
    self.__target(*self.__args, **self.__kwargs)
  File "/usr/local/lib/python2.6/dist-packages/rpyc/utils/server.py", line 178, in _authenticate_and_serve_client
    self._serve_client(sock2, credentials)
  File "/usr/local/lib/python2.6/dist-packages/rpyc/utils/server.py", line 201, in _serve_client
    conn._init_service()
  File "/usr/local/lib/python2.6/dist-packages/rpyc/core/protocol.py", line 150, in _init_service
    self._local_root.on_connect()
  File "/home/alice/tesla/CredentialMgr/credentialmanager.py", line 18, in on_connect
    debug( "Welkom")
TypeError: 'module' object is not callable

Exception TypeError: "'module' object is not callable" in <bound method Connection.__del__ of <rpyc.core.protocol.Connection 'conn23' object at 0xb6ebad2c>> ignored
Exception in thread Thread-24:
Traceback (most recent call last):
  File "/usr/lib/python2.6/threading.py", line 532, in __bootstrap_inner
    self.run()
  File "/usr/lib/python2.6/threading.py", line 484, in run
    self.__target(*self.__args, **self.__kwargs)
  File "/usr/local/lib/python2.6/dist-packages/rpyc/utils/server.py", line 178, in _authenticate_and_serve_client
    self._serve_client(sock2, credentials)
  File "/usr/local/lib/python2.6/dist-packages/rpyc/utils/server.py", line 201, in _serve_client
    conn._init_service()
  File "/usr/local/lib/python2.6/dist-packages/rpyc/core/protocol.py", line 150, in _init_service
    self._local_root.on_connect()
  File "/home/alice/tesla/CredentialMgr/credentialmanager.py", line 18, in on_connect
    debug( "Welkom")
TypeError: 'module' object is not callable

Exception TypeError: "'module' object is not callable" in <bound method Connection.__del__ of <rpyc.core.protocol.Connection 'conn24' object at 0xb6ebac6c>> ignored
Exception in thread Thread-25:
Traceback (most recent call last):
  File "/usr/lib/python2.6/threading.py", line 532, in __bootstrap_inner
    self.run()
  File "/usr/lib/python2.6/threading.py", line 484, in run
    self.__target(*self.__args, **self.__kwargs)
  File "/usr/local/lib/python2.6/dist-packages/rpyc/utils/server.py", line 178, in _authenticate_and_serve_client
    self._serve_client(sock2, credentials)
  File "/usr/local/lib/python2.6/dist-packages/rpyc/utils/server.py", line 201, in _serve_client
    conn._init_service()
  File "/usr/local/lib/python2.6/dist-packages/rpyc/core/protocol.py", line 150, in _init_service
    self._local_root.on_connect()
  File "/home/alice/tesla/CredentialMgr/credentialmanager.py", line 18, in on_connect
    debug( "Welkom")
TypeError: 'module' object is not callable

Exception TypeError: "'module' object is not callable" in <bound method Connection.__del__ of <rpyc.core.protocol.Connection 'conn25' object at 0xb6ebad8c>> ignored
Exception in thread Thread-26:
Traceback (most recent call last):
  File "/usr/lib/python2.6/threading.py", line 532, in __bootstrap_inner
    self.run()
  File "/usr/lib/python2.6/threading.py", line 484, in run
    self.__target(*self.__args, **self.__kwargs)
  File "/usr/local/lib/python2.6/dist-packages/rpyc/utils/server.py", line 178, in _authenticate_and_serve_client
    self._serve_client(sock2, credentials)
  File "/usr/local/lib/python2.6/dist-packages/rpyc/utils/server.py", line 201, in _serve_client
    conn._init_service()
  File "/usr/local/lib/python2.6/dist-packages/rpyc/core/protocol.py", line 150, in _init_service
    self._local_root.on_connect()
  File "/home/alice/tesla/CredentialMgr/credentialmanager.py", line 18, in on_connect
    debug( "Welkom")
TypeError: 'module' object is not callable

Exception TypeError: "'module' object is not callable" in <bound method Connection.__del__ of <rpyc.core.protocol.Connection 'conn26' object at 0xb6ebadcc>> ignored
Exception in thread Thread-27:
Traceback (most recent call last):
  File "/usr/lib/python2.6/threading.py", line 532, in __bootstrap_inner
    self.run()
  File "/usr/lib/python2.6/threading.py", line 484, in run
    self.__target(*self.__args, **self.__kwargs)
  File "/usr/local/lib/python2.6/dist-packages/rpyc/utils/server.py", line 178, in _authenticate_and_serve_client
    self._serve_client(sock2, credentials)
  File "/usr/local/lib/python2.6/dist-packages/rpyc/utils/server.py", line 201, in _serve_client
    conn._init_service()
  File "/usr/local/lib/python2.6/dist-packages/rpyc/core/protocol.py", line 150, in _init_service
    self._local_root.on_connect()
  File "/home/alice/tesla/CredentialMgr/credentialmanager.py", line 18, in on_connect
    debug( "Welkom")
TypeError: 'module' object is not callable

Exception TypeError: "'module' object is not callable" in <bound method Connection.__del__ of <rpyc.core.protocol.Connection 'conn27' object at 0xb6ebad4c>> ignored
Exception in thread Thread-28:
Traceback (most recent call last):
  File "/usr/lib/python2.6/threading.py", line 532, in __bootstrap_inner
    self.run()
  File "/usr/lib/python2.6/threading.py", line 484, in run
    self.__target(*self.__args, **self.__kwargs)
  File "/usr/local/lib/python2.6/dist-packages/rpyc/utils/server.py", line 178, in _authenticate_and_serve_client
    self._serve_client(sock2, credentials)
  File "/usr/local/lib/python2.6/dist-packages/rpyc/utils/server.py", line 201, in _serve_client
    conn._init_service()
  File "/usr/local/lib/python2.6/dist-packages/rpyc/core/protocol.py", line 150, in _init_service
    self._local_root.on_connect()
  File "/home/alice/tesla/CredentialMgr/credentialmanager.py", line 18, in on_connect
    debug( "Welkom")
TypeError: 'module' object is not callable

Exception TypeError: "'module' object is not callable" in <bound method Connection.__del__ of <rpyc.core.protocol.Connection 'conn28' object at 0xb6ebad2c>> ignored
Exception in thread Thread-29:
Traceback (most recent call last):
  File "/usr/lib/python2.6/threading.py", line 532, in __bootstrap_inner
    self.run()
  File "/usr/lib/python2.6/threading.py", line 484, in run
    self.__target(*self.__args, **self.__kwargs)
  File "/usr/local/lib/python2.6/dist-packages/rpyc/utils/server.py", line 178, in _authenticate_and_serve_client
    self._serve_client(sock2, credentials)
  File "/usr/local/lib/python2.6/dist-packages/rpyc/utils/server.py", line 201, in _serve_client
    conn._init_service()
  File "/usr/local/lib/python2.6/dist-packages/rpyc/core/protocol.py", line 150, in _init_service
    self._local_root.on_connect()
  File "/home/alice/tesla/CredentialMgr/credentialmanager.py", line 18, in on_connect
    debug( "Welkom")
TypeError: 'module' object is not callable

Exception TypeError: "'module' object is not callable" in <bound method Connection.__del__ of <rpyc.core.protocol.Connection 'conn29' object at 0xb6ebac6c>> ignored
Exception in thread Thread-30:
Traceback (most recent call last):
  File "/usr/lib/python2.6/threading.py", line 532, in __bootstrap_inner
    self.run()
  File "/usr/lib/python2.6/threading.py", line 484, in run
    self.__target(*self.__args, **self.__kwargs)
  File "/usr/local/lib/python2.6/dist-packages/rpyc/utils/server.py", line 178, in _authenticate_and_serve_client
    self._serve_client(sock2, credentials)
  File "/usr/local/lib/python2.6/dist-packages/rpyc/utils/server.py", line 201, in _serve_client
    conn._init_service()
  File "/usr/local/lib/python2.6/dist-packages/rpyc/core/protocol.py", line 150, in _init_service
    self._local_root.on_connect()
  File "/home/alice/tesla/CredentialMgr/credentialmanager.py", line 18, in on_connect
    debug( "Welkom")
TypeError: 'module' object is not callable

Exception TypeError: "'module' object is not callable" in <bound method Connection.__del__ of <rpyc.core.protocol.Connection 'conn30' object at 0xb6ebad8c>> ignored
Exception in thread Thread-31:
Traceback (most recent call last):
  File "/usr/lib/python2.6/threading.py", line 532, in __bootstrap_inner
    self.run()
  File "/usr/lib/python2.6/threading.py", line 484, in run
    self.__target(*self.__args, **self.__kwargs)
  File "/usr/local/lib/python2.6/dist-packages/rpyc/utils/server.py", line 178, in _authenticate_and_serve_client
    self._serve_client(sock2, credentials)
  File "/usr/local/lib/python2.6/dist-packages/rpyc/utils/server.py", line 201, in _serve_client
    conn._init_service()
  File "/usr/local/lib/python2.6/dist-packages/rpyc/core/protocol.py", line 150, in _init_service
    self._local_root.on_connect()
  File "/home/alice/tesla/CredentialMgr/credentialmanager.py", line 18, in on_connect
    debug( "Welkom")
TypeError: 'module' object is not callable

Exception TypeError: "'module' object is not callable" in <bound method Connection.__del__ of <rpyc.core.protocol.Connection 'conn31' object at 0xb6ebadcc>> ignored
Exception in thread Thread-32:
Traceback (most recent call last):
  File "/usr/lib/python2.6/threading.py", line 532, in __bootstrap_inner
    self.run()
  File "/usr/lib/python2.6/threading.py", line 484, in run
    self.__target(*self.__args, **self.__kwargs)
  File "/usr/local/lib/python2.6/dist-packages/rpyc/utils/server.py", line 178, in _authenticate_and_serve_client
    self._serve_client(sock2, credentials)
  File "/usr/local/lib/python2.6/dist-packages/rpyc/utils/server.py", line 201, in _serve_client
    conn._init_service()
  File "/usr/local/lib/python2.6/dist-packages/rpyc/core/protocol.py", line 150, in _init_service
    self._local_root.on_connect()
  File "/home/alice/tesla/CredentialMgr/credentialmanager.py", line 18, in on_connect
    debug( "Welkom")
TypeError: 'module' object is not callable

Exception TypeError: "'module' object is not callable" in <bound method Connection.__del__ of <rpyc.core.protocol.Connection 'conn32' object at 0xb6ebad4c>> ignored
Exception in thread Thread-33:
Traceback (most recent call last):
  File "/usr/lib/python2.6/threading.py", line 532, in __bootstrap_inner
    self.run()
  File "/usr/lib/python2.6/threading.py", line 484, in run
    self.__target(*self.__args, **self.__kwargs)
  File "/usr/local/lib/python2.6/dist-packages/rpyc/utils/server.py", line 178, in _authenticate_and_serve_client
    self._serve_client(sock2, credentials)
  File "/usr/local/lib/python2.6/dist-packages/rpyc/utils/server.py", line 201, in _serve_client
    conn._init_service()
  File "/usr/local/lib/python2.6/dist-packages/rpyc/core/protocol.py", line 150, in _init_service
    self._local_root.on_connect()
  File "/home/alice/tesla/CredentialMgr/credentialmanager.py", line 18, in on_connect
    debug( "Welkom")
TypeError: 'module' object is not callable

Exception TypeError: "'module' object is not callable" in <bound method Connection.__del__ of <rpyc.core.protocol.Connection 'conn33' object at 0xb6ebad2c>> ignored
Exception in thread Thread-34:
Traceback (most recent call last):
  File "/usr/lib/python2.6/threading.py", line 532, in __bootstrap_inner
    self.run()
  File "/usr/lib/python2.6/threading.py", line 484, in run
    self.__target(*self.__args, **self.__kwargs)
  File "/usr/local/lib/python2.6/dist-packages/rpyc/utils/server.py", line 178, in _authenticate_and_serve_client
    self._serve_client(sock2, credentials)
  File "/usr/local/lib/python2.6/dist-packages/rpyc/utils/server.py", line 201, in _serve_client
    conn._init_service()
  File "/usr/local/lib/python2.6/dist-packages/rpyc/core/protocol.py", line 150, in _init_service
    self._local_root.on_connect()
  File "/home/alice/tesla/CredentialMgr/credentialmanager.py", line 18, in on_connect
    debug( "Welkom")
TypeError: 'module' object is not callable

Exception TypeError: "'module' object is not callable" in <bound method Connection.__del__ of <rpyc.core.protocol.Connection 'conn34' object at 0xb6ebac6c>> ignored
Exception in thread Thread-35:
Traceback (most recent call last):
  File "/usr/lib/python2.6/threading.py", line 532, in __bootstrap_inner
    self.run()
  File "/usr/lib/python2.6/threading.py", line 484, in run
    self.__target(*self.__args, **self.__kwargs)
  File "/usr/local/lib/python2.6/dist-packages/rpyc/utils/server.py", line 178, in _authenticate_and_serve_client
    self._serve_client(sock2, credentials)
  File "/usr/local/lib/python2.6/dist-packages/rpyc/utils/server.py", line 201, in _serve_client
    conn._init_service()
  File "/usr/local/lib/python2.6/dist-packages/rpyc/core/protocol.py", line 150, in _init_service
    self._local_root.on_connect()
  File "/home/alice/tesla/CredentialMgr/credentialmanager.py", line 18, in on_connect
    debug( "Welkom")
TypeError: 'module' object is not callable

Exception TypeError: "'module' object is not callable" in <bound method Connection.__del__ of <rpyc.core.protocol.Connection 'conn35' object at 0xb6ebad8c>> ignored
Exception in thread Thread-36:
Traceback (most recent call last):
  File "/usr/lib/python2.6/threading.py", line 532, in __bootstrap_inner
    self.run()
  File "/usr/lib/python2.6/threading.py", line 484, in run
    self.__target(*self.__args, **self.__kwargs)
  File "/usr/local/lib/python2.6/dist-packages/rpyc/utils/server.py", line 178, in _authenticate_and_serve_client
    self._serve_client(sock2, credentials)
  File "/usr/local/lib/python2.6/dist-packages/rpyc/utils/server.py", line 201, in _serve_client
    conn._init_service()
  File "/usr/local/lib/python2.6/dist-packages/rpyc/core/protocol.py", line 150, in _init_service
    self._local_root.on_connect()
  File "/home/alice/tesla/CredentialMgr/credentialmanager.py", line 18, in on_connect
    debug( "Welkom")
TypeError: 'module' object is not callable

Exception TypeError: "'module' object is not callable" in <bound method Connection.__del__ of <rpyc.core.protocol.Connection 'conn36' object at 0xb6ebadcc>> ignored
Exception in thread Thread-37:
Traceback (most recent call last):
  File "/usr/lib/python2.6/threading.py", line 532, in __bootstrap_inner
    self.run()
  File "/usr/lib/python2.6/threading.py", line 484, in run
    self.__target(*self.__args, **self.__kwargs)
  File "/usr/local/lib/python2.6/dist-packages/rpyc/utils/server.py", line 178, in _authenticate_and_serve_client
    self._serve_client(sock2, credentials)
  File "/usr/local/lib/python2.6/dist-packages/rpyc/utils/server.py", line 201, in _serve_client
    conn._init_service()
  File "/usr/local/lib/python2.6/dist-packages/rpyc/core/protocol.py", line 150, in _init_service
    self._local_root.on_connect()
  File "/home/alice/tesla/CredentialMgr/credentialmanager.py", line 18, in on_connect
    debug( "Welkom")
TypeError: 'module' object is not callable

Exception TypeError: "'module' object is not callable" in <bound method Connection.__del__ of <rpyc.core.protocol.Connection 'conn37' object at 0xb6ebad4c>> ignored
Exception in thread Thread-38:
Traceback (most recent call last):
  File "/usr/lib/python2.6/threading.py", line 532, in __bootstrap_inner
    self.run()
  File "/usr/lib/python2.6/threading.py", line 484, in run
    self.__target(*self.__args, **self.__kwargs)
  File "/usr/local/lib/python2.6/dist-packages/rpyc/utils/server.py", line 178, in _authenticate_and_serve_client
    self._serve_client(sock2, credentials)
  File "/usr/local/lib/python2.6/dist-packages/rpyc/utils/server.py", line 201, in _serve_client
    conn._init_service()
  File "/usr/local/lib/python2.6/dist-packages/rpyc/core/protocol.py", line 150, in _init_service
    self._local_root.on_connect()
  File "/home/alice/tesla/CredentialMgr/credentialmanager.py", line 18, in on_connect
    debug( "Welkom")
TypeError: 'module' object is not callable

Exception TypeError: "'module' object is not callable" in <bound method Connection.__del__ of <rpyc.core.protocol.Connection 'conn38' object at 0xb6ebad2c>> ignored
Exception in thread Thread-39:
Traceback (most recent call last):
  File "/usr/lib/python2.6/threading.py", line 532, in __bootstrap_inner
    self.run()
  File "/usr/lib/python2.6/threading.py", line 484, in run
    self.__target(*self.__args, **self.__kwargs)
  File "/usr/local/lib/python2.6/dist-packages/rpyc/utils/server.py", line 178, in _authenticate_and_serve_client
    self._serve_client(sock2, credentials)
  File "/usr/local/lib/python2.6/dist-packages/rpyc/utils/server.py", line 201, in _serve_client
    conn._init_service()
  File "/usr/local/lib/python2.6/dist-packages/rpyc/core/protocol.py", line 150, in _init_service
    self._local_root.on_connect()
  File "/home/alice/tesla/CredentialMgr/credentialmanager.py", line 18, in on_connect
    debug( "Welkom")
TypeError: 'module' object is not callable

Exception TypeError: "'module' object is not callable" in <bound method Connection.__del__ of <rpyc.core.protocol.Connection 'conn39' object at 0xb6ebac6c>> ignored
Exception in thread Thread-40:
Traceback (most recent call last):
  File "/usr/lib/python2.6/threading.py", line 532, in __bootstrap_inner
    self.run()
  File "/usr/lib/python2.6/threading.py", line 484, in run
    self.__target(*self.__args, **self.__kwargs)
  File "/usr/local/lib/python2.6/dist-packages/rpyc/utils/server.py", line 178, in _authenticate_and_serve_client
    self._serve_client(sock2, credentials)
  File "/usr/local/lib/python2.6/dist-packages/rpyc/utils/server.py", line 201, in _serve_client
    conn._init_service()
  File "/usr/local/lib/python2.6/dist-packages/rpyc/core/protocol.py", line 150, in _init_service
    self._local_root.on_connect()
  File "/home/alice/tesla/CredentialMgr/credentialmanager.py", line 18, in on_connect
    debug( "Welkom")
TypeError: 'module' object is not callable

Exception TypeError: "'module' object is not callable" in <bound method Connection.__del__ of <rpyc.core.protocol.Connection 'conn40' object at 0xb6ebad8c>> ignored
Exception in thread Thread-41:
Traceback (most recent call last):
  File "/usr/lib/python2.6/threading.py", line 532, in __bootstrap_inner
    self.run()
  File "/usr/lib/python2.6/threading.py", line 484, in run
    self.__target(*self.__args, **self.__kwargs)
  File "/usr/local/lib/python2.6/dist-packages/rpyc/utils/server.py", line 178, in _authenticate_and_serve_client
    self._serve_client(sock2, credentials)
  File "/usr/local/lib/python2.6/dist-packages/rpyc/utils/server.py", line 201, in _serve_client
    conn._init_service()
  File "/usr/local/lib/python2.6/dist-packages/rpyc/core/protocol.py", line 150, in _init_service
    self._local_root.on_connect()
  File "/home/alice/tesla/CredentialMgr/credentialmanager.py", line 18, in on_connect
    debug( "Welkom")
TypeError: 'module' object is not callable

Exception TypeError: "'module' object is not callable" in <bound method Connection.__del__ of <rpyc.core.protocol.Connection 'conn41' object at 0xb6ebadcc>> ignored
Exception in thread Thread-42:
Traceback (most recent call last):
  File "/usr/lib/python2.6/threading.py", line 532, in __bootstrap_inner
    self.run()
  File "/usr/lib/python2.6/threading.py", line 484, in run
    self.__target(*self.__args, **self.__kwargs)
  File "/usr/local/lib/python2.6/dist-packages/rpyc/utils/server.py", line 178, in _authenticate_and_serve_client
    self._serve_client(sock2, credentials)
  File "/usr/local/lib/python2.6/dist-packages/rpyc/utils/server.py", line 201, in _serve_client
    conn._init_service()
  File "/usr/local/lib/python2.6/dist-packages/rpyc/core/protocol.py", line 150, in _init_service
    self._local_root.on_connect()
  File "/home/alice/tesla/CredentialMgr/credentialmanager.py", line 18, in on_connect
    debug( "Welkom")
TypeError: 'module' object is not callable

Exception TypeError: "'module' object is not callable" in <bound method Connection.__del__ of <rpyc.core.protocol.Connection 'conn42' object at 0xb6ebad4c>> ignored
Exception in thread Thread-43:
Traceback (most recent call last):
  File "/usr/lib/python2.6/threading.py", line 532, in __bootstrap_inner
    self.run()
  File "/usr/lib/python2.6/threading.py", line 484, in run
    self.__target(*self.__args, **self.__kwargs)
  File "/usr/local/lib/python2.6/dist-packages/rpyc/utils/server.py", line 178, in _authenticate_and_serve_client
    self._serve_client(sock2, credentials)
  File "/usr/local/lib/python2.6/dist-packages/rpyc/utils/server.py", line 201, in _serve_client
    conn._init_service()
  File "/usr/local/lib/python2.6/dist-packages/rpyc/core/protocol.py", line 150, in _init_service
    self._local_root.on_connect()
  File "/home/alice/tesla/CredentialMgr/credentialmanager.py", line 18, in on_connect
    debug( "Welkom")
TypeError: 'module' object is not callable

Exception TypeError: "'module' object is not callable" in <bound method Connection.__del__ of <rpyc.core.protocol.Connection 'conn43' object at 0xb6ebad2c>> ignored
Exception in thread Thread-44:
Traceback (most recent call last):
  File "/usr/lib/python2.6/threading.py", line 532, in __bootstrap_inner
    self.run()
  File "/usr/lib/python2.6/threading.py", line 484, in run
    self.__target(*self.__args, **self.__kwargs)
  File "/usr/local/lib/python2.6/dist-packages/rpyc/utils/server.py", line 178, in _authenticate_and_serve_client
    self._serve_client(sock2, credentials)
  File "/usr/local/lib/python2.6/dist-packages/rpyc/utils/server.py", line 201, in _serve_client
    conn._init_service()
  File "/usr/local/lib/python2.6/dist-packages/rpyc/core/protocol.py", line 150, in _init_service
    self._local_root.on_connect()
  File "/home/alice/tesla/CredentialMgr/credentialmanager.py", line 18, in on_connect
    debug( "Welkom")
TypeError: 'module' object is not callable

Exception TypeError: "'module' object is not callable" in <bound method Connection.__del__ of <rpyc.core.protocol.Connection 'conn44' object at 0xb6ebac6c>> ignored
Exception in thread Thread-45:
Traceback (most recent call last):
  File "/usr/lib/python2.6/threading.py", line 532, in __bootstrap_inner
    self.run()
  File "/usr/lib/python2.6/threading.py", line 484, in run
    self.__target(*self.__args, **self.__kwargs)
  File "/usr/local/lib/python2.6/dist-packages/rpyc/utils/server.py", line 178, in _authenticate_and_serve_client
    self._serve_client(sock2, credentials)
  File "/usr/local/lib/python2.6/dist-packages/rpyc/utils/server.py", line 201, in _serve_client
    conn._init_service()
  File "/usr/local/lib/python2.6/dist-packages/rpyc/core/protocol.py", line 150, in _init_service
    self._local_root.on_connect()
  File "/home/alice/tesla/CredentialMgr/credentialmanager.py", line 18, in on_connect
    debug( "Welkom")
TypeError: 'module' object is not callable

Exception TypeError: "'module' object is not callable" in <bound method Connection.__del__ of <rpyc.core.protocol.Connection 'conn45' object at 0xb6ebad8c>> ignored
/home/alice/tesla/admin-scripts/watchdog_credentialmanager.sh: line 9: 28472 Killed                  nohup /usr/bin/python $filename
