Traceback (most recent call last):
  File "fetchData.py", line 195, in <module>
    vehicle_state_data = vehicle.vehicle_state
  File "/home/alice/tesla_aggregator_bart/pytesla/vehicle.py", line 54, in vehicle_state
    return self._command('vehicle_state')
  File "/home/alice/tesla_aggregator_bart/pytesla/vehicle.py", line 60, in _command
    return self._conn.read_json_path(('vehicles/%s/command/%s' + get) % (self.id, verb))
  File "/home/alice/tesla_aggregator_bart/pytesla/connection.py", line 89, in read_json_path
    return Session.read_json(self, _ENDPOINT + path, post_data)
  File "/home/alice/tesla_aggregator_bart/pytesla/connection.py", line 65, in read_json
    data = self.read_url( url, post_data ).read()
  File "/home/alice/tesla_aggregator_bart/pytesla/connection.py", line 59, in read_url
    f = req.open(self._encode(url), data=post)
  File "/usr/lib/python2.6/urllib2.py", line 397, in open
    response = meth(req, response)
  File "/usr/lib/python2.6/urllib2.py", line 510, in http_response
    'http', request, response, code, msg, hdrs)
  File "/usr/lib/python2.6/urllib2.py", line 435, in error
    return self._call_chain(*args)
  File "/usr/lib/python2.6/urllib2.py", line 369, in _call_chain
    result = func(*args)
  File "/usr/lib/python2.6/urllib2.py", line 518, in http_error_default
    raise HTTPError(req.get_full_url(), code, msg, hdrs, fp)
urllib2.HTTPError: HTTP Error 503: Service Not Available
Traceback (most recent call last):
  File "fetchData.py", line 140, in <module>
    except Error as e:
NameError: name 'Error' is not defined
